ERROR 2025-08-14 19:13:45,150[PID 87647] django.request- Internal Server Error: /api/webhook/paystack/
Traceback (most recent call last):
  File "/home/ubuntu/e-commerce_backend/myenv/lib/python3.10/site-packages/django/db/models/query.py", line 946, in get_or_create
    return self.get(**kwargs), False
  File "/home/ubuntu/e-commerce_backend/myenv/lib/python3.10/site-packages/django/db/models/query.py", line 633, in get
    raise self.model.DoesNotExist(
store.models.Payment.DoesNotExist: Payment matching query does not exist.

During handling of the above exception, another exception occurred:

Traceback (most recent call last):
  File "/home/ubuntu/e-commerce_backend/myenv/lib/python3.10/site-packages/django/core/handlers/exception.py", line 55, in inner
    response = get_response(request)
  File "/home/ubuntu/e-commerce_backend/myenv/lib/python3.10/site-packages/django/core/handlers/base.py", line 197, in _get_response
    response = wrapped_callback(request, *callback_args, **callback_kwargs)
  File "/home/ubuntu/e-commerce_backend/myenv/lib/python3.10/site-packages/django/views/decorators/csrf.py", line 65, in _view_wrapper
    return view_func(request, *args, **kwargs)
  File "/home/ubuntu/e-commerce_backend/myenv/lib/python3.10/site-packages/django/views/generic/base.py", line 105, in view
    return self.dispatch(request, *args, **kwargs)
  File "/home/ubuntu/e-commerce_backend/myenv/lib/python3.10/site-packages/django/utils/decorators.py", line 48, in _wrapper
    return bound_method(*args, **kwargs)
  File "/home/ubuntu/e-commerce_backend/myenv/lib/python3.10/site-packages/django/views/decorators/csrf.py", line 65, in _view_wrapper
    return view_func(request, *args, **kwargs)
  File "/home/ubuntu/e-commerce_backend/myenv/lib/python3.10/site-packages/rest_framework/views.py", line 515, in dispatch
    response = self.handle_exception(exc)
  File "/home/ubuntu/e-commerce_backend/myenv/lib/python3.10/site-packages/rest_framework/views.py", line 475, in handle_exception
    self.raise_uncaught_exception(exc)
  File "/home/ubuntu/e-commerce_backend/myenv/lib/python3.10/site-packages/rest_framework/views.py", line 486, in raise_uncaught_exception
    raise exc
  File "/home/ubuntu/e-commerce_backend/myenv/lib/python3.10/site-packages/rest_framework/views.py", line 512, in dispatch
    response = handler(request, *args, **kwargs)
  File "/home/ubuntu/e-commerce_backend/myenv/lib/python3.10/site-packages/django/views/decorators/csrf.py", line 65, in _view_wrapper
    return view_func(request, *args, **kwargs)
  File "/home/ubuntu/e-commerce_backend/shopsite/store/webhook.py", line 92, in post
    payment, created = Payment.objects.get_or_create(
  File "/home/ubuntu/e-commerce_backend/myenv/lib/python3.10/site-packages/django/db/models/manager.py", line 87, in manager_method
    return getattr(self.get_queryset(), name)(*args, **kwargs)
  File "/home/ubuntu/e-commerce_backend/myenv/lib/python3.10/site-packages/django/db/models/query.py", line 948, in get_or_create
    params = self._extract_model_params(defaults, **kwargs)
  File "/home/ubuntu/e-commerce_backend/myenv/lib/python3.10/site-packages/django/db/models/query.py", line 1046, in _extract_model_params
    raise exceptions.FieldError(
django.core.exceptions.FieldError: Invalid field name(s) for model Payment: 'currency'.
ERROR 2025-08-14 19:15:27,083[PID 87647] django.request- Internal Server Error: /api/webhook/paystack/
Traceback (most recent call last):
  File "/home/ubuntu/e-commerce_backend/myenv/lib/python3.10/site-packages/django/db/models/query.py", line 946, in get_or_create
    return self.get(**kwargs), False
  File "/home/ubuntu/e-commerce_backend/myenv/lib/python3.10/site-packages/django/db/models/query.py", line 633, in get
    raise self.model.DoesNotExist(
store.models.Payment.DoesNotExist: Payment matching query does not exist.

During handling of the above exception, another exception occurred:

Traceback (most recent call last):
  File "/home/ubuntu/e-commerce_backend/myenv/lib/python3.10/site-packages/django/core/handlers/exception.py", line 55, in inner
    response = get_response(request)
  File "/home/ubuntu/e-commerce_backend/myenv/lib/python3.10/site-packages/django/core/handlers/base.py", line 197, in _get_response
    response = wrapped_callback(request, *callback_args, **callback_kwargs)
  File "/home/ubuntu/e-commerce_backend/myenv/lib/python3.10/site-packages/django/views/decorators/csrf.py", line 65, in _view_wrapper
    return view_func(request, *args, **kwargs)
  File "/home/ubuntu/e-commerce_backend/myenv/lib/python3.10/site-packages/django/views/generic/base.py", line 105, in view
    return self.dispatch(request, *args, **kwargs)
  File "/home/ubuntu/e-commerce_backend/myenv/lib/python3.10/site-packages/django/utils/decorators.py", line 48, in _wrapper
    return bound_method(*args, **kwargs)
  File "/home/ubuntu/e-commerce_backend/myenv/lib/python3.10/site-packages/django/views/decorators/csrf.py", line 65, in _view_wrapper
    return view_func(request, *args, **kwargs)
  File "/home/ubuntu/e-commerce_backend/myenv/lib/python3.10/site-packages/rest_framework/views.py", line 515, in dispatch
    response = self.handle_exception(exc)
  File "/home/ubuntu/e-commerce_backend/myenv/lib/python3.10/site-packages/rest_framework/views.py", line 475, in handle_exception
    self.raise_uncaught_exception(exc)
  File "/home/ubuntu/e-commerce_backend/myenv/lib/python3.10/site-packages/rest_framework/views.py", line 486, in raise_uncaught_exception
    raise exc
  File "/home/ubuntu/e-commerce_backend/myenv/lib/python3.10/site-packages/rest_framework/views.py", line 512, in dispatch
    response = handler(request, *args, **kwargs)
  File "/home/ubuntu/e-commerce_backend/myenv/lib/python3.10/site-packages/django/views/decorators/csrf.py", line 65, in _view_wrapper
    return view_func(request, *args, **kwargs)
  File "/home/ubuntu/e-commerce_backend/shopsite/store/webhook.py", line 92, in post
    payment, created = Payment.objects.get_or_create(
  File "/home/ubuntu/e-commerce_backend/myenv/lib/python3.10/site-packages/django/db/models/manager.py", line 87, in manager_method
    return getattr(self.get_queryset(), name)(*args, **kwargs)
  File "/home/ubuntu/e-commerce_backend/myenv/lib/python3.10/site-packages/django/db/models/query.py", line 948, in get_or_create
    params = self._extract_model_params(defaults, **kwargs)
  File "/home/ubuntu/e-commerce_backend/myenv/lib/python3.10/site-packages/django/db/models/query.py", line 1046, in _extract_model_params
    raise exceptions.FieldError(
django.core.exceptions.FieldError: Invalid field name(s) for model Payment: 'currency'.
ERROR 2025-08-14 19:18:10,479[PID 87647] django.request- Internal Server Error: /api/webhook/paystack/
Traceback (most recent call last):
  File "/home/ubuntu/e-commerce_backend/myenv/lib/python3.10/site-packages/django/db/models/query.py", line 946, in get_or_create
    return self.get(**kwargs), False
  File "/home/ubuntu/e-commerce_backend/myenv/lib/python3.10/site-packages/django/db/models/query.py", line 633, in get
    raise self.model.DoesNotExist(
store.models.Payment.DoesNotExist: Payment matching query does not exist.

During handling of the above exception, another exception occurred:

Traceback (most recent call last):
  File "/home/ubuntu/e-commerce_backend/myenv/lib/python3.10/site-packages/django/core/handlers/exception.py", line 55, in inner
    response = get_response(request)
  File "/home/ubuntu/e-commerce_backend/myenv/lib/python3.10/site-packages/django/core/handlers/base.py", line 197, in _get_response
    response = wrapped_callback(request, *callback_args, **callback_kwargs)
  File "/home/ubuntu/e-commerce_backend/myenv/lib/python3.10/site-packages/django/views/decorators/csrf.py", line 65, in _view_wrapper
    return view_func(request, *args, **kwargs)
  File "/home/ubuntu/e-commerce_backend/myenv/lib/python3.10/site-packages/django/views/generic/base.py", line 105, in view
    return self.dispatch(request, *args, **kwargs)
  File "/home/ubuntu/e-commerce_backend/myenv/lib/python3.10/site-packages/django/utils/decorators.py", line 48, in _wrapper
    return bound_method(*args, **kwargs)
  File "/home/ubuntu/e-commerce_backend/myenv/lib/python3.10/site-packages/django/views/decorators/csrf.py", line 65, in _view_wrapper
    return view_func(request, *args, **kwargs)
  File "/home/ubuntu/e-commerce_backend/myenv/lib/python3.10/site-packages/rest_framework/views.py", line 515, in dispatch
    response = self.handle_exception(exc)
  File "/home/ubuntu/e-commerce_backend/myenv/lib/python3.10/site-packages/rest_framework/views.py", line 475, in handle_exception
    self.raise_uncaught_exception(exc)
  File "/home/ubuntu/e-commerce_backend/myenv/lib/python3.10/site-packages/rest_framework/views.py", line 486, in raise_uncaught_exception
    raise exc
  File "/home/ubuntu/e-commerce_backend/myenv/lib/python3.10/site-packages/rest_framework/views.py", line 512, in dispatch
    response = handler(request, *args, **kwargs)
  File "/home/ubuntu/e-commerce_backend/myenv/lib/python3.10/site-packages/django/views/decorators/csrf.py", line 65, in _view_wrapper
    return view_func(request, *args, **kwargs)
  File "/home/ubuntu/e-commerce_backend/shopsite/store/webhook.py", line 92, in post
    payment, created = Payment.objects.get_or_create(
  File "/home/ubuntu/e-commerce_backend/myenv/lib/python3.10/site-packages/django/db/models/manager.py", line 87, in manager_method
    return getattr(self.get_queryset(), name)(*args, **kwargs)
  File "/home/ubuntu/e-commerce_backend/myenv/lib/python3.10/site-packages/django/db/models/query.py", line 948, in get_or_create
    params = self._extract_model_params(defaults, **kwargs)
  File "/home/ubuntu/e-commerce_backend/myenv/lib/python3.10/site-packages/django/db/models/query.py", line 1046, in _extract_model_params
    raise exceptions.FieldError(
django.core.exceptions.FieldError: Invalid field name(s) for model Payment: 'currency'.
ERROR 2025-08-14 19:18:38,040[PID 87647] django.request- Internal Server Error: /api/webhook/paystack/
Traceback (most recent call last):
  File "/home/ubuntu/e-commerce_backend/myenv/lib/python3.10/site-packages/django/db/models/query.py", line 946, in get_or_create
    return self.get(**kwargs), False
  File "/home/ubuntu/e-commerce_backend/myenv/lib/python3.10/site-packages/django/db/models/query.py", line 633, in get
    raise self.model.DoesNotExist(
store.models.Payment.DoesNotExist: Payment matching query does not exist.

During handling of the above exception, another exception occurred:

Traceback (most recent call last):
  File "/home/ubuntu/e-commerce_backend/myenv/lib/python3.10/site-packages/django/core/handlers/exception.py", line 55, in inner
    response = get_response(request)
  File "/home/ubuntu/e-commerce_backend/myenv/lib/python3.10/site-packages/django/core/handlers/base.py", line 197, in _get_response
    response = wrapped_callback(request, *callback_args, **callback_kwargs)
  File "/home/ubuntu/e-commerce_backend/myenv/lib/python3.10/site-packages/django/views/decorators/csrf.py", line 65, in _view_wrapper
    return view_func(request, *args, **kwargs)
  File "/home/ubuntu/e-commerce_backend/myenv/lib/python3.10/site-packages/django/views/generic/base.py", line 105, in view
    return self.dispatch(request, *args, **kwargs)
  File "/home/ubuntu/e-commerce_backend/myenv/lib/python3.10/site-packages/django/utils/decorators.py", line 48, in _wrapper
    return bound_method(*args, **kwargs)
  File "/home/ubuntu/e-commerce_backend/myenv/lib/python3.10/site-packages/django/views/decorators/csrf.py", line 65, in _view_wrapper
    return view_func(request, *args, **kwargs)
  File "/home/ubuntu/e-commerce_backend/myenv/lib/python3.10/site-packages/rest_framework/views.py", line 515, in dispatch
    response = self.handle_exception(exc)
  File "/home/ubuntu/e-commerce_backend/myenv/lib/python3.10/site-packages/rest_framework/views.py", line 475, in handle_exception
    self.raise_uncaught_exception(exc)
  File "/home/ubuntu/e-commerce_backend/myenv/lib/python3.10/site-packages/rest_framework/views.py", line 486, in raise_uncaught_exception
    raise exc
  File "/home/ubuntu/e-commerce_backend/myenv/lib/python3.10/site-packages/rest_framework/views.py", line 512, in dispatch
    response = handler(request, *args, **kwargs)
  File "/home/ubuntu/e-commerce_backend/myenv/lib/python3.10/site-packages/django/views/decorators/csrf.py", line 65, in _view_wrapper
    return view_func(request, *args, **kwargs)
  File "/home/ubuntu/e-commerce_backend/shopsite/store/webhook.py", line 92, in post
    payment, created = Payment.objects.get_or_create(
  File "/home/ubuntu/e-commerce_backend/myenv/lib/python3.10/site-packages/django/db/models/manager.py", line 87, in manager_method
    return getattr(self.get_queryset(), name)(*args, **kwargs)
  File "/home/ubuntu/e-commerce_backend/myenv/lib/python3.10/site-packages/django/db/models/query.py", line 948, in get_or_create
    params = self._extract_model_params(defaults, **kwargs)
  File "/home/ubuntu/e-commerce_backend/myenv/lib/python3.10/site-packages/django/db/models/query.py", line 1046, in _extract_model_params
    raise exceptions.FieldError(
django.core.exceptions.FieldError: Invalid field name(s) for model Payment: 'currency'.
ERROR 2025-08-14 19:21:31,500[PID 87727] django.request- Internal Server Error: /api/webhook/paystack/
Traceback (most recent call last):
  File "/home/ubuntu/e-commerce_backend/myenv/lib/python3.10/site-packages/django/db/models/query.py", line 946, in get_or_create
    return self.get(**kwargs), False
  File "/home/ubuntu/e-commerce_backend/myenv/lib/python3.10/site-packages/django/db/models/query.py", line 633, in get
    raise self.model.DoesNotExist(
store.models.Payment.DoesNotExist: Payment matching query does not exist.

During handling of the above exception, another exception occurred:

Traceback (most recent call last):
  File "/home/ubuntu/e-commerce_backend/myenv/lib/python3.10/site-packages/django/db/backends/utils.py", line 105, in _execute
    return self.cursor.execute(sql, params)
psycopg2.errors.NotNullViolation: null value in column "customer_id" of relation "store_payment" violates not-null constraint
DETAIL:  Failing row contains (6, e6823a0b-310e-42f5-8dc2-bbcdb37221a0, 3.00, PENDING, 2025-08-14 19:21:31.413999+00, null, order_1a6c4680-49ef-4013-bdc6-95dbf2c29e7f_1755198795, null, null, null, KES).


The above exception was the direct cause of the following exception:

Traceback (most recent call last):
  File "/home/ubuntu/e-commerce_backend/myenv/lib/python3.10/site-packages/django/core/handlers/exception.py", line 55, in inner
    response = get_response(request)
  File "/home/ubuntu/e-commerce_backend/myenv/lib/python3.10/site-packages/django/core/handlers/base.py", line 197, in _get_response
    response = wrapped_callback(request, *callback_args, **callback_kwargs)
  File "/home/ubuntu/e-commerce_backend/myenv/lib/python3.10/site-packages/django/views/decorators/csrf.py", line 65, in _view_wrapper
    return view_func(request, *args, **kwargs)
  File "/home/ubuntu/e-commerce_backend/myenv/lib/python3.10/site-packages/django/views/generic/base.py", line 105, in view
    return self.dispatch(request, *args, **kwargs)
  File "/home/ubuntu/e-commerce_backend/myenv/lib/python3.10/site-packages/django/utils/decorators.py", line 48, in _wrapper
    return bound_method(*args, **kwargs)
  File "/home/ubuntu/e-commerce_backend/myenv/lib/python3.10/site-packages/django/views/decorators/csrf.py", line 65, in _view_wrapper
    return view_func(request, *args, **kwargs)
  File "/home/ubuntu/e-commerce_backend/myenv/lib/python3.10/site-packages/rest_framework/views.py", line 515, in dispatch
    response = self.handle_exception(exc)
  File "/home/ubuntu/e-commerce_backend/myenv/lib/python3.10/site-packages/rest_framework/views.py", line 475, in handle_exception
    self.raise_uncaught_exception(exc)
  File "/home/ubuntu/e-commerce_backend/myenv/lib/python3.10/site-packages/rest_framework/views.py", line 486, in raise_uncaught_exception
    raise exc
  File "/home/ubuntu/e-commerce_backend/myenv/lib/python3.10/site-packages/rest_framework/views.py", line 512, in dispatch
    response = handler(request, *args, **kwargs)
  File "/home/ubuntu/e-commerce_backend/myenv/lib/python3.10/site-packages/django/views/decorators/csrf.py", line 65, in _view_wrapper
    return view_func(request, *args, **kwargs)
  File "/home/ubuntu/e-commerce_backend/shopsite/store/webhook.py", line 92, in post
    payment, created = Payment.objects.get_or_create(
  File "/home/ubuntu/e-commerce_backend/myenv/lib/python3.10/site-packages/django/db/models/manager.py", line 87, in manager_method
    return getattr(self.get_queryset(), name)(*args, **kwargs)
  File "/home/ubuntu/e-commerce_backend/myenv/lib/python3.10/site-packages/django/db/models/query.py", line 953, in get_or_create
    return self.create(**params), True
  File "/home/ubuntu/e-commerce_backend/myenv/lib/python3.10/site-packages/django/db/models/query.py", line 663, in create
    obj.save(force_insert=True, using=self.db)
  File "/home/ubuntu/e-commerce_backend/myenv/lib/python3.10/site-packages/django/db/models/base.py", line 902, in save
    self.save_base(
  File "/home/ubuntu/e-commerce_backend/myenv/lib/python3.10/site-packages/django/db/models/base.py", line 1008, in save_base
    updated = self._save_table(
  File "/home/ubuntu/e-commerce_backend/myenv/lib/python3.10/site-packages/django/db/models/base.py", line 1169, in _save_table
    results = self._do_insert(
  File "/home/ubuntu/e-commerce_backend/myenv/lib/python3.10/site-packages/django/db/models/base.py", line 1210, in _do_insert
    return manager._insert(
  File "/home/ubuntu/e-commerce_backend/myenv/lib/python3.10/site-packages/django/db/models/manager.py", line 87, in manager_method
    return getattr(self.get_queryset(), name)(*args, **kwargs)
  File "/home/ubuntu/e-commerce_backend/myenv/lib/python3.10/site-packages/django/db/models/query.py", line 1868, in _insert
    return query.get_compiler(using=using).execute_sql(returning_fields)
  File "/home/ubuntu/e-commerce_backend/myenv/lib/python3.10/site-packages/django/db/models/sql/compiler.py", line 1882, in execute_sql
    cursor.execute(sql, params)
  File "/home/ubuntu/e-commerce_backend/myenv/lib/python3.10/site-packages/django/db/backends/utils.py", line 79, in execute
    return self._execute_with_wrappers(
  File "/home/ubuntu/e-commerce_backend/myenv/lib/python3.10/site-packages/django/db/backends/utils.py", line 92, in _execute_with_wrappers
    return executor(sql, params, many, context)
  File "/home/ubuntu/e-commerce_backend/myenv/lib/python3.10/site-packages/django/db/backends/utils.py", line 100, in _execute
    with self.db.wrap_database_errors:
  File "/home/ubuntu/e-commerce_backend/myenv/lib/python3.10/site-packages/django/db/utils.py", line 91, in __exit__
    raise dj_exc_value.with_traceback(traceback) from exc_value
  File "/home/ubuntu/e-commerce_backend/myenv/lib/python3.10/site-packages/django/db/backends/utils.py", line 105, in _execute
    return self.cursor.execute(sql, params)
django.db.utils.IntegrityError: null value in column "customer_id" of relation "store_payment" violates not-null constraint
DETAIL:  Failing row contains (6, e6823a0b-310e-42f5-8dc2-bbcdb37221a0, 3.00, PENDING, 2025-08-14 19:21:31.413999+00, null, order_1a6c4680-49ef-4013-bdc6-95dbf2c29e7f_1755198795, null, null, null, KES).

ERROR 2025-08-14 19:21:51,942[PID 87727] django.request- Internal Server Error: /api/webhook/paystack/
Traceback (most recent call last):
  File "/home/ubuntu/e-commerce_backend/myenv/lib/python3.10/site-packages/django/db/models/query.py", line 946, in get_or_create
    return self.get(**kwargs), False
  File "/home/ubuntu/e-commerce_backend/myenv/lib/python3.10/site-packages/django/db/models/query.py", line 633, in get
    raise self.model.DoesNotExist(
store.models.Payment.DoesNotExist: Payment matching query does not exist.

During handling of the above exception, another exception occurred:

Traceback (most recent call last):
  File "/home/ubuntu/e-commerce_backend/myenv/lib/python3.10/site-packages/django/db/backends/utils.py", line 105, in _execute
    return self.cursor.execute(sql, params)
psycopg2.errors.NotNullViolation: null value in column "customer_id" of relation "store_payment" violates not-null constraint
DETAIL:  Failing row contains (7, b37a999d-0e62-4b19-996f-b947ed0604e7, 3.00, PENDING, 2025-08-14 19:21:51.939709+00, null, order_1a6c4680-49ef-4013-bdc6-95dbf2c29e7f_1755199267, null, null, null, KES).


The above exception was the direct cause of the following exception:

Traceback (most recent call last):
  File "/home/ubuntu/e-commerce_backend/myenv/lib/python3.10/site-packages/django/core/handlers/exception.py", line 55, in inner
    response = get_response(request)
  File "/home/ubuntu/e-commerce_backend/myenv/lib/python3.10/site-packages/django/core/handlers/base.py", line 197, in _get_response
    response = wrapped_callback(request, *callback_args, **callback_kwargs)
  File "/home/ubuntu/e-commerce_backend/myenv/lib/python3.10/site-packages/django/views/decorators/csrf.py", line 65, in _view_wrapper
    return view_func(request, *args, **kwargs)
  File "/home/ubuntu/e-commerce_backend/myenv/lib/python3.10/site-packages/django/views/generic/base.py", line 105, in view
    return self.dispatch(request, *args, **kwargs)
  File "/home/ubuntu/e-commerce_backend/myenv/lib/python3.10/site-packages/django/utils/decorators.py", line 48, in _wrapper
    return bound_method(*args, **kwargs)
  File "/home/ubuntu/e-commerce_backend/myenv/lib/python3.10/site-packages/django/views/decorators/csrf.py", line 65, in _view_wrapper
    return view_func(request, *args, **kwargs)
  File "/home/ubuntu/e-commerce_backend/myenv/lib/python3.10/site-packages/rest_framework/views.py", line 515, in dispatch
    response = self.handle_exception(exc)
  File "/home/ubuntu/e-commerce_backend/myenv/lib/python3.10/site-packages/rest_framework/views.py", line 475, in handle_exception
    self.raise_uncaught_exception(exc)
  File "/home/ubuntu/e-commerce_backend/myenv/lib/python3.10/site-packages/rest_framework/views.py", line 486, in raise_uncaught_exception
    raise exc
  File "/home/ubuntu/e-commerce_backend/myenv/lib/python3.10/site-packages/rest_framework/views.py", line 512, in dispatch
    response = handler(request, *args, **kwargs)
  File "/home/ubuntu/e-commerce_backend/myenv/lib/python3.10/site-packages/django/views/decorators/csrf.py", line 65, in _view_wrapper
    return view_func(request, *args, **kwargs)
  File "/home/ubuntu/e-commerce_backend/shopsite/store/webhook.py", line 92, in post
    payment, created = Payment.objects.get_or_create(
  File "/home/ubuntu/e-commerce_backend/myenv/lib/python3.10/site-packages/django/db/models/manager.py", line 87, in manager_method
    return getattr(self.get_queryset(), name)(*args, **kwargs)
  File "/home/ubuntu/e-commerce_backend/myenv/lib/python3.10/site-packages/django/db/models/query.py", line 953, in get_or_create
    return self.create(**params), True
  File "/home/ubuntu/e-commerce_backend/myenv/lib/python3.10/site-packages/django/db/models/query.py", line 663, in create
    obj.save(force_insert=True, using=self.db)
  File "/home/ubuntu/e-commerce_backend/myenv/lib/python3.10/site-packages/django/db/models/base.py", line 902, in save
    self.save_base(
  File "/home/ubuntu/e-commerce_backend/myenv/lib/python3.10/site-packages/django/db/models/base.py", line 1008, in save_base
    updated = self._save_table(
  File "/home/ubuntu/e-commerce_backend/myenv/lib/python3.10/site-packages/django/db/models/base.py", line 1169, in _save_table
    results = self._do_insert(
  File "/home/ubuntu/e-commerce_backend/myenv/lib/python3.10/site-packages/django/db/models/base.py", line 1210, in _do_insert
    return manager._insert(
  File "/home/ubuntu/e-commerce_backend/myenv/lib/python3.10/site-packages/django/db/models/manager.py", line 87, in manager_method
    return getattr(self.get_queryset(), name)(*args, **kwargs)
  File "/home/ubuntu/e-commerce_backend/myenv/lib/python3.10/site-packages/django/db/models/query.py", line 1868, in _insert
    return query.get_compiler(using=using).execute_sql(returning_fields)
  File "/home/ubuntu/e-commerce_backend/myenv/lib/python3.10/site-packages/django/db/models/sql/compiler.py", line 1882, in execute_sql
    cursor.execute(sql, params)
  File "/home/ubuntu/e-commerce_backend/myenv/lib/python3.10/site-packages/django/db/backends/utils.py", line 79, in execute
    return self._execute_with_wrappers(
  File "/home/ubuntu/e-commerce_backend/myenv/lib/python3.10/site-packages/django/db/backends/utils.py", line 92, in _execute_with_wrappers
    return executor(sql, params, many, context)
  File "/home/ubuntu/e-commerce_backend/myenv/lib/python3.10/site-packages/django/db/backends/utils.py", line 100, in _execute
    with self.db.wrap_database_errors:
  File "/home/ubuntu/e-commerce_backend/myenv/lib/python3.10/site-packages/django/db/utils.py", line 91, in __exit__
    raise dj_exc_value.with_traceback(traceback) from exc_value
  File "/home/ubuntu/e-commerce_backend/myenv/lib/python3.10/site-packages/django/db/backends/utils.py", line 105, in _execute
    return self.cursor.execute(sql, params)
django.db.utils.IntegrityError: null value in column "customer_id" of relation "store_payment" violates not-null constraint
DETAIL:  Failing row contains (7, b37a999d-0e62-4b19-996f-b947ed0604e7, 3.00, PENDING, 2025-08-14 19:21:51.939709+00, null, order_1a6c4680-49ef-4013-bdc6-95dbf2c29e7f_1755199267, null, null, null, KES).

ERROR 2025-08-14 19:21:58,427[PID 87727] django.request- Internal Server Error: /api/webhook/paystack/
Traceback (most recent call last):
  File "/home/ubuntu/e-commerce_backend/myenv/lib/python3.10/site-packages/django/db/models/query.py", line 946, in get_or_create
    return self.get(**kwargs), False
  File "/home/ubuntu/e-commerce_backend/myenv/lib/python3.10/site-packages/django/db/models/query.py", line 633, in get
    raise self.model.DoesNotExist(
store.models.Payment.DoesNotExist: Payment matching query does not exist.

During handling of the above exception, another exception occurred:

Traceback (most recent call last):
  File "/home/ubuntu/e-commerce_backend/myenv/lib/python3.10/site-packages/django/db/backends/utils.py", line 105, in _execute
    return self.cursor.execute(sql, params)
psycopg2.errors.NotNullViolation: null value in column "customer_id" of relation "store_payment" violates not-null constraint
DETAIL:  Failing row contains (8, f3aae9dd-141f-4495-b11e-6a9ec121e0ab, 3.00, PENDING, 2025-08-14 19:21:58.42474+00, null, order_1a6c4680-49ef-4013-bdc6-95dbf2c29e7f_1755198191, null, null, null, KES).


The above exception was the direct cause of the following exception:

Traceback (most recent call last):
  File "/home/ubuntu/e-commerce_backend/myenv/lib/python3.10/site-packages/django/core/handlers/exception.py", line 55, in inner
    response = get_response(request)
  File "/home/ubuntu/e-commerce_backend/myenv/lib/python3.10/site-packages/django/core/handlers/base.py", line 197, in _get_response
    response = wrapped_callback(request, *callback_args, **callback_kwargs)
  File "/home/ubuntu/e-commerce_backend/myenv/lib/python3.10/site-packages/django/views/decorators/csrf.py", line 65, in _view_wrapper
    return view_func(request, *args, **kwargs)
  File "/home/ubuntu/e-commerce_backend/myenv/lib/python3.10/site-packages/django/views/generic/base.py", line 105, in view
    return self.dispatch(request, *args, **kwargs)
  File "/home/ubuntu/e-commerce_backend/myenv/lib/python3.10/site-packages/django/utils/decorators.py", line 48, in _wrapper
    return bound_method(*args, **kwargs)
  File "/home/ubuntu/e-commerce_backend/myenv/lib/python3.10/site-packages/django/views/decorators/csrf.py", line 65, in _view_wrapper
    return view_func(request, *args, **kwargs)
  File "/home/ubuntu/e-commerce_backend/myenv/lib/python3.10/site-packages/rest_framework/views.py", line 515, in dispatch
    response = self.handle_exception(exc)
  File "/home/ubuntu/e-commerce_backend/myenv/lib/python3.10/site-packages/rest_framework/views.py", line 475, in handle_exception
    self.raise_uncaught_exception(exc)
  File "/home/ubuntu/e-commerce_backend/myenv/lib/python3.10/site-packages/rest_framework/views.py", line 486, in raise_uncaught_exception
    raise exc
  File "/home/ubuntu/e-commerce_backend/myenv/lib/python3.10/site-packages/rest_framework/views.py", line 512, in dispatch
    response = handler(request, *args, **kwargs)
  File "/home/ubuntu/e-commerce_backend/myenv/lib/python3.10/site-packages/django/views/decorators/csrf.py", line 65, in _view_wrapper
    return view_func(request, *args, **kwargs)
  File "/home/ubuntu/e-commerce_backend/shopsite/store/webhook.py", line 92, in post
    payment, created = Payment.objects.get_or_create(
  File "/home/ubuntu/e-commerce_backend/myenv/lib/python3.10/site-packages/django/db/models/manager.py", line 87, in manager_method
    return getattr(self.get_queryset(), name)(*args, **kwargs)
  File "/home/ubuntu/e-commerce_backend/myenv/lib/python3.10/site-packages/django/db/models/query.py", line 953, in get_or_create
    return self.create(**params), True
  File "/home/ubuntu/e-commerce_backend/myenv/lib/python3.10/site-packages/django/db/models/query.py", line 663, in create
    obj.save(force_insert=True, using=self.db)
  File "/home/ubuntu/e-commerce_backend/myenv/lib/python3.10/site-packages/django/db/models/base.py", line 902, in save
    self.save_base(
  File "/home/ubuntu/e-commerce_backend/myenv/lib/python3.10/site-packages/django/db/models/base.py", line 1008, in save_base
    updated = self._save_table(
  File "/home/ubuntu/e-commerce_backend/myenv/lib/python3.10/site-packages/django/db/models/base.py", line 1169, in _save_table
    results = self._do_insert(
  File "/home/ubuntu/e-commerce_backend/myenv/lib/python3.10/site-packages/django/db/models/base.py", line 1210, in _do_insert
    return manager._insert(
  File "/home/ubuntu/e-commerce_backend/myenv/lib/python3.10/site-packages/django/db/models/manager.py", line 87, in manager_method
    return getattr(self.get_queryset(), name)(*args, **kwargs)
  File "/home/ubuntu/e-commerce_backend/myenv/lib/python3.10/site-packages/django/db/models/query.py", line 1868, in _insert
    return query.get_compiler(using=using).execute_sql(returning_fields)
  File "/home/ubuntu/e-commerce_backend/myenv/lib/python3.10/site-packages/django/db/models/sql/compiler.py", line 1882, in execute_sql
    cursor.execute(sql, params)
  File "/home/ubuntu/e-commerce_backend/myenv/lib/python3.10/site-packages/django/db/backends/utils.py", line 79, in execute
    return self._execute_with_wrappers(
  File "/home/ubuntu/e-commerce_backend/myenv/lib/python3.10/site-packages/django/db/backends/utils.py", line 92, in _execute_with_wrappers
    return executor(sql, params, many, context)
  File "/home/ubuntu/e-commerce_backend/myenv/lib/python3.10/site-packages/django/db/backends/utils.py", line 100, in _execute
    with self.db.wrap_database_errors:
  File "/home/ubuntu/e-commerce_backend/myenv/lib/python3.10/site-packages/django/db/utils.py", line 91, in __exit__
    raise dj_exc_value.with_traceback(traceback) from exc_value
  File "/home/ubuntu/e-commerce_backend/myenv/lib/python3.10/site-packages/django/db/backends/utils.py", line 105, in _execute
    return self.cursor.execute(sql, params)
django.db.utils.IntegrityError: null value in column "customer_id" of relation "store_payment" violates not-null constraint
DETAIL:  Failing row contains (8, f3aae9dd-141f-4495-b11e-6a9ec121e0ab, 3.00, PENDING, 2025-08-14 19:21:58.42474+00, null, order_1a6c4680-49ef-4013-bdc6-95dbf2c29e7f_1755198191, null, null, null, KES).

ERROR 2025-08-14 19:24:40,247[PID 87727] django.request- Internal Server Error: /api/webhook/paystack/
Traceback (most recent call last):
  File "/home/ubuntu/e-commerce_backend/myenv/lib/python3.10/site-packages/django/db/models/query.py", line 946, in get_or_create
    return self.get(**kwargs), False
  File "/home/ubuntu/e-commerce_backend/myenv/lib/python3.10/site-packages/django/db/models/query.py", line 633, in get
    raise self.model.DoesNotExist(
store.models.Payment.DoesNotExist: Payment matching query does not exist.

During handling of the above exception, another exception occurred:

Traceback (most recent call last):
  File "/home/ubuntu/e-commerce_backend/myenv/lib/python3.10/site-packages/django/db/backends/utils.py", line 105, in _execute
    return self.cursor.execute(sql, params)
psycopg2.errors.NotNullViolation: null value in column "customer_id" of relation "store_payment" violates not-null constraint
DETAIL:  Failing row contains (9, 1987c461-c2e7-4855-bb68-199c5b3b6d34, 3.00, PENDING, 2025-08-14 19:24:40.245036+00, null, order_1a6c4680-49ef-4013-bdc6-95dbf2c29e7f_1755198795, null, null, null, KES).


The above exception was the direct cause of the following exception:

Traceback (most recent call last):
  File "/home/ubuntu/e-commerce_backend/myenv/lib/python3.10/site-packages/django/core/handlers/exception.py", line 55, in inner
    response = get_response(request)
  File "/home/ubuntu/e-commerce_backend/myenv/lib/python3.10/site-packages/django/core/handlers/base.py", line 197, in _get_response
    response = wrapped_callback(request, *callback_args, **callback_kwargs)
  File "/home/ubuntu/e-commerce_backend/myenv/lib/python3.10/site-packages/django/views/decorators/csrf.py", line 65, in _view_wrapper
    return view_func(request, *args, **kwargs)
  File "/home/ubuntu/e-commerce_backend/myenv/lib/python3.10/site-packages/django/views/generic/base.py", line 105, in view
    return self.dispatch(request, *args, **kwargs)
  File "/home/ubuntu/e-commerce_backend/myenv/lib/python3.10/site-packages/django/utils/decorators.py", line 48, in _wrapper
    return bound_method(*args, **kwargs)
  File "/home/ubuntu/e-commerce_backend/myenv/lib/python3.10/site-packages/django/views/decorators/csrf.py", line 65, in _view_wrapper
    return view_func(request, *args, **kwargs)
  File "/home/ubuntu/e-commerce_backend/myenv/lib/python3.10/site-packages/rest_framework/views.py", line 515, in dispatch
    response = self.handle_exception(exc)
  File "/home/ubuntu/e-commerce_backend/myenv/lib/python3.10/site-packages/rest_framework/views.py", line 475, in handle_exception
    self.raise_uncaught_exception(exc)
  File "/home/ubuntu/e-commerce_backend/myenv/lib/python3.10/site-packages/rest_framework/views.py", line 486, in raise_uncaught_exception
    raise exc
  File "/home/ubuntu/e-commerce_backend/myenv/lib/python3.10/site-packages/rest_framework/views.py", line 512, in dispatch
    response = handler(request, *args, **kwargs)
  File "/home/ubuntu/e-commerce_backend/myenv/lib/python3.10/site-packages/django/views/decorators/csrf.py", line 65, in _view_wrapper
    return view_func(request, *args, **kwargs)
  File "/home/ubuntu/e-commerce_backend/shopsite/store/webhook.py", line 92, in post
    payment, created = Payment.objects.get_or_create(
  File "/home/ubuntu/e-commerce_backend/myenv/lib/python3.10/site-packages/django/db/models/manager.py", line 87, in manager_method
    return getattr(self.get_queryset(), name)(*args, **kwargs)
  File "/home/ubuntu/e-commerce_backend/myenv/lib/python3.10/site-packages/django/db/models/query.py", line 953, in get_or_create
    return self.create(**params), True
  File "/home/ubuntu/e-commerce_backend/myenv/lib/python3.10/site-packages/django/db/models/query.py", line 663, in create
    obj.save(force_insert=True, using=self.db)
  File "/home/ubuntu/e-commerce_backend/myenv/lib/python3.10/site-packages/django/db/models/base.py", line 902, in save
    self.save_base(
  File "/home/ubuntu/e-commerce_backend/myenv/lib/python3.10/site-packages/django/db/models/base.py", line 1008, in save_base
    updated = self._save_table(
  File "/home/ubuntu/e-commerce_backend/myenv/lib/python3.10/site-packages/django/db/models/base.py", line 1169, in _save_table
    results = self._do_insert(
  File "/home/ubuntu/e-commerce_backend/myenv/lib/python3.10/site-packages/django/db/models/base.py", line 1210, in _do_insert
    return manager._insert(
  File "/home/ubuntu/e-commerce_backend/myenv/lib/python3.10/site-packages/django/db/models/manager.py", line 87, in manager_method
    return getattr(self.get_queryset(), name)(*args, **kwargs)
  File "/home/ubuntu/e-commerce_backend/myenv/lib/python3.10/site-packages/django/db/models/query.py", line 1868, in _insert
    return query.get_compiler(using=using).execute_sql(returning_fields)
  File "/home/ubuntu/e-commerce_backend/myenv/lib/python3.10/site-packages/django/db/models/sql/compiler.py", line 1882, in execute_sql
    cursor.execute(sql, params)
  File "/home/ubuntu/e-commerce_backend/myenv/lib/python3.10/site-packages/django/db/backends/utils.py", line 79, in execute
    return self._execute_with_wrappers(
  File "/home/ubuntu/e-commerce_backend/myenv/lib/python3.10/site-packages/django/db/backends/utils.py", line 92, in _execute_with_wrappers
    return executor(sql, params, many, context)
  File "/home/ubuntu/e-commerce_backend/myenv/lib/python3.10/site-packages/django/db/backends/utils.py", line 100, in _execute
    with self.db.wrap_database_errors:
  File "/home/ubuntu/e-commerce_backend/myenv/lib/python3.10/site-packages/django/db/utils.py", line 91, in __exit__
    raise dj_exc_value.with_traceback(traceback) from exc_value
  File "/home/ubuntu/e-commerce_backend/myenv/lib/python3.10/site-packages/django/db/backends/utils.py", line 105, in _execute
    return self.cursor.execute(sql, params)
django.db.utils.IntegrityError: null value in column "customer_id" of relation "store_payment" violates not-null constraint
DETAIL:  Failing row contains (9, 1987c461-c2e7-4855-bb68-199c5b3b6d34, 3.00, PENDING, 2025-08-14 19:24:40.245036+00, null, order_1a6c4680-49ef-4013-bdc6-95dbf2c29e7f_1755198795, null, null, null, KES).

ERROR 2025-08-14 19:27:04,436[PID 87727] django.request- Internal Server Error: /api/webhook/paystack/
Traceback (most recent call last):
  File "/home/ubuntu/e-commerce_backend/myenv/lib/python3.10/site-packages/django/db/models/query.py", line 946, in get_or_create
    return self.get(**kwargs), False
  File "/home/ubuntu/e-commerce_backend/myenv/lib/python3.10/site-packages/django/db/models/query.py", line 633, in get
    raise self.model.DoesNotExist(
store.models.Payment.DoesNotExist: Payment matching query does not exist.

During handling of the above exception, another exception occurred:

Traceback (most recent call last):
  File "/home/ubuntu/e-commerce_backend/myenv/lib/python3.10/site-packages/django/db/backends/utils.py", line 105, in _execute
    return self.cursor.execute(sql, params)
psycopg2.errors.NotNullViolation: null value in column "customer_id" of relation "store_payment" violates not-null constraint
DETAIL:  Failing row contains (10, 96262b66-4ea7-458d-926d-984425c42bd1, 3.00, PENDING, 2025-08-14 19:27:04.433888+00, null, order_1a6c4680-49ef-4013-bdc6-95dbf2c29e7f_1755199267, null, null, null, KES).


The above exception was the direct cause of the following exception:

Traceback (most recent call last):
  File "/home/ubuntu/e-commerce_backend/myenv/lib/python3.10/site-packages/django/core/handlers/exception.py", line 55, in inner
    response = get_response(request)
  File "/home/ubuntu/e-commerce_backend/myenv/lib/python3.10/site-packages/django/core/handlers/base.py", line 197, in _get_response
    response = wrapped_callback(request, *callback_args, **callback_kwargs)
  File "/home/ubuntu/e-commerce_backend/myenv/lib/python3.10/site-packages/django/views/decorators/csrf.py", line 65, in _view_wrapper
    return view_func(request, *args, **kwargs)
  File "/home/ubuntu/e-commerce_backend/myenv/lib/python3.10/site-packages/django/views/generic/base.py", line 105, in view
    return self.dispatch(request, *args, **kwargs)
  File "/home/ubuntu/e-commerce_backend/myenv/lib/python3.10/site-packages/django/utils/decorators.py", line 48, in _wrapper
    return bound_method(*args, **kwargs)
  File "/home/ubuntu/e-commerce_backend/myenv/lib/python3.10/site-packages/django/views/decorators/csrf.py", line 65, in _view_wrapper
    return view_func(request, *args, **kwargs)
  File "/home/ubuntu/e-commerce_backend/myenv/lib/python3.10/site-packages/rest_framework/views.py", line 515, in dispatch
    response = self.handle_exception(exc)
  File "/home/ubuntu/e-commerce_backend/myenv/lib/python3.10/site-packages/rest_framework/views.py", line 475, in handle_exception
    self.raise_uncaught_exception(exc)
  File "/home/ubuntu/e-commerce_backend/myenv/lib/python3.10/site-packages/rest_framework/views.py", line 486, in raise_uncaught_exception
    raise exc
  File "/home/ubuntu/e-commerce_backend/myenv/lib/python3.10/site-packages/rest_framework/views.py", line 512, in dispatch
    response = handler(request, *args, **kwargs)
  File "/home/ubuntu/e-commerce_backend/myenv/lib/python3.10/site-packages/django/views/decorators/csrf.py", line 65, in _view_wrapper
    return view_func(request, *args, **kwargs)
  File "/home/ubuntu/e-commerce_backend/shopsite/store/webhook.py", line 92, in post
    payment, created = Payment.objects.get_or_create(
  File "/home/ubuntu/e-commerce_backend/myenv/lib/python3.10/site-packages/django/db/models/manager.py", line 87, in manager_method
    return getattr(self.get_queryset(), name)(*args, **kwargs)
  File "/home/ubuntu/e-commerce_backend/myenv/lib/python3.10/site-packages/django/db/models/query.py", line 953, in get_or_create
    return self.create(**params), True
  File "/home/ubuntu/e-commerce_backend/myenv/lib/python3.10/site-packages/django/db/models/query.py", line 663, in create
    obj.save(force_insert=True, using=self.db)
  File "/home/ubuntu/e-commerce_backend/myenv/lib/python3.10/site-packages/django/db/models/base.py", line 902, in save
    self.save_base(
  File "/home/ubuntu/e-commerce_backend/myenv/lib/python3.10/site-packages/django/db/models/base.py", line 1008, in save_base
    updated = self._save_table(
  File "/home/ubuntu/e-commerce_backend/myenv/lib/python3.10/site-packages/django/db/models/base.py", line 1169, in _save_table
    results = self._do_insert(
  File "/home/ubuntu/e-commerce_backend/myenv/lib/python3.10/site-packages/django/db/models/base.py", line 1210, in _do_insert
    return manager._insert(
  File "/home/ubuntu/e-commerce_backend/myenv/lib/python3.10/site-packages/django/db/models/manager.py", line 87, in manager_method
    return getattr(self.get_queryset(), name)(*args, **kwargs)
  File "/home/ubuntu/e-commerce_backend/myenv/lib/python3.10/site-packages/django/db/models/query.py", line 1868, in _insert
    return query.get_compiler(using=using).execute_sql(returning_fields)
  File "/home/ubuntu/e-commerce_backend/myenv/lib/python3.10/site-packages/django/db/models/sql/compiler.py", line 1882, in execute_sql
    cursor.execute(sql, params)
  File "/home/ubuntu/e-commerce_backend/myenv/lib/python3.10/site-packages/django/db/backends/utils.py", line 79, in execute
    return self._execute_with_wrappers(
  File "/home/ubuntu/e-commerce_backend/myenv/lib/python3.10/site-packages/django/db/backends/utils.py", line 92, in _execute_with_wrappers
    return executor(sql, params, many, context)
  File "/home/ubuntu/e-commerce_backend/myenv/lib/python3.10/site-packages/django/db/backends/utils.py", line 100, in _execute
    with self.db.wrap_database_errors:
  File "/home/ubuntu/e-commerce_backend/myenv/lib/python3.10/site-packages/django/db/utils.py", line 91, in __exit__
    raise dj_exc_value.with_traceback(traceback) from exc_value
  File "/home/ubuntu/e-commerce_backend/myenv/lib/python3.10/site-packages/django/db/backends/utils.py", line 105, in _execute
    return self.cursor.execute(sql, params)
django.db.utils.IntegrityError: null value in column "customer_id" of relation "store_payment" violates not-null constraint
DETAIL:  Failing row contains (10, 96262b66-4ea7-458d-926d-984425c42bd1, 3.00, PENDING, 2025-08-14 19:27:04.433888+00, null, order_1a6c4680-49ef-4013-bdc6-95dbf2c29e7f_1755199267, null, null, null, KES).

ERROR 2025-08-14 19:27:49,671[PID 87727] django.request- Internal Server Error: /api/webhook/paystack/
Traceback (most recent call last):
  File "/home/ubuntu/e-commerce_backend/myenv/lib/python3.10/site-packages/django/db/models/query.py", line 946, in get_or_create
    return self.get(**kwargs), False
  File "/home/ubuntu/e-commerce_backend/myenv/lib/python3.10/site-packages/django/db/models/query.py", line 633, in get
    raise self.model.DoesNotExist(
store.models.Payment.DoesNotExist: Payment matching query does not exist.

During handling of the above exception, another exception occurred:

Traceback (most recent call last):
  File "/home/ubuntu/e-commerce_backend/myenv/lib/python3.10/site-packages/django/db/backends/utils.py", line 105, in _execute
    return self.cursor.execute(sql, params)
psycopg2.errors.NotNullViolation: null value in column "customer_id" of relation "store_payment" violates not-null constraint
DETAIL:  Failing row contains (11, 1c2ef27f-ace1-4cbd-a805-9da039df2eba, 3.00, PENDING, 2025-08-14 19:27:49.668176+00, null, order_1a6c4680-49ef-4013-bdc6-95dbf2c29e7f_1755198795, null, null, null, KES).


The above exception was the direct cause of the following exception:

Traceback (most recent call last):
  File "/home/ubuntu/e-commerce_backend/myenv/lib/python3.10/site-packages/django/core/handlers/exception.py", line 55, in inner
    response = get_response(request)
  File "/home/ubuntu/e-commerce_backend/myenv/lib/python3.10/site-packages/django/core/handlers/base.py", line 197, in _get_response
    response = wrapped_callback(request, *callback_args, **callback_kwargs)
  File "/home/ubuntu/e-commerce_backend/myenv/lib/python3.10/site-packages/django/views/decorators/csrf.py", line 65, in _view_wrapper
    return view_func(request, *args, **kwargs)
  File "/home/ubuntu/e-commerce_backend/myenv/lib/python3.10/site-packages/django/views/generic/base.py", line 105, in view
    return self.dispatch(request, *args, **kwargs)
  File "/home/ubuntu/e-commerce_backend/myenv/lib/python3.10/site-packages/django/utils/decorators.py", line 48, in _wrapper
    return bound_method(*args, **kwargs)
  File "/home/ubuntu/e-commerce_backend/myenv/lib/python3.10/site-packages/django/views/decorators/csrf.py", line 65, in _view_wrapper
    return view_func(request, *args, **kwargs)
  File "/home/ubuntu/e-commerce_backend/myenv/lib/python3.10/site-packages/rest_framework/views.py", line 515, in dispatch
    response = self.handle_exception(exc)
  File "/home/ubuntu/e-commerce_backend/myenv/lib/python3.10/site-packages/rest_framework/views.py", line 475, in handle_exception
    self.raise_uncaught_exception(exc)
  File "/home/ubuntu/e-commerce_backend/myenv/lib/python3.10/site-packages/rest_framework/views.py", line 486, in raise_uncaught_exception
    raise exc
  File "/home/ubuntu/e-commerce_backend/myenv/lib/python3.10/site-packages/rest_framework/views.py", line 512, in dispatch
    response = handler(request, *args, **kwargs)
  File "/home/ubuntu/e-commerce_backend/myenv/lib/python3.10/site-packages/django/views/decorators/csrf.py", line 65, in _view_wrapper
    return view_func(request, *args, **kwargs)
  File "/home/ubuntu/e-commerce_backend/shopsite/store/webhook.py", line 92, in post
    payment, created = Payment.objects.get_or_create(
  File "/home/ubuntu/e-commerce_backend/myenv/lib/python3.10/site-packages/django/db/models/manager.py", line 87, in manager_method
    return getattr(self.get_queryset(), name)(*args, **kwargs)
  File "/home/ubuntu/e-commerce_backend/myenv/lib/python3.10/site-packages/django/db/models/query.py", line 953, in get_or_create
    return self.create(**params), True
  File "/home/ubuntu/e-commerce_backend/myenv/lib/python3.10/site-packages/django/db/models/query.py", line 663, in create
    obj.save(force_insert=True, using=self.db)
  File "/home/ubuntu/e-commerce_backend/myenv/lib/python3.10/site-packages/django/db/models/base.py", line 902, in save
    self.save_base(
  File "/home/ubuntu/e-commerce_backend/myenv/lib/python3.10/site-packages/django/db/models/base.py", line 1008, in save_base
    updated = self._save_table(
  File "/home/ubuntu/e-commerce_backend/myenv/lib/python3.10/site-packages/django/db/models/base.py", line 1169, in _save_table
    results = self._do_insert(
  File "/home/ubuntu/e-commerce_backend/myenv/lib/python3.10/site-packages/django/db/models/base.py", line 1210, in _do_insert
    return manager._insert(
  File "/home/ubuntu/e-commerce_backend/myenv/lib/python3.10/site-packages/django/db/models/manager.py", line 87, in manager_method
    return getattr(self.get_queryset(), name)(*args, **kwargs)
  File "/home/ubuntu/e-commerce_backend/myenv/lib/python3.10/site-packages/django/db/models/query.py", line 1868, in _insert
    return query.get_compiler(using=using).execute_sql(returning_fields)
  File "/home/ubuntu/e-commerce_backend/myenv/lib/python3.10/site-packages/django/db/models/sql/compiler.py", line 1882, in execute_sql
    cursor.execute(sql, params)
  File "/home/ubuntu/e-commerce_backend/myenv/lib/python3.10/site-packages/django/db/backends/utils.py", line 79, in execute
    return self._execute_with_wrappers(
  File "/home/ubuntu/e-commerce_backend/myenv/lib/python3.10/site-packages/django/db/backends/utils.py", line 92, in _execute_with_wrappers
    return executor(sql, params, many, context)
  File "/home/ubuntu/e-commerce_backend/myenv/lib/python3.10/site-packages/django/db/backends/utils.py", line 100, in _execute
    with self.db.wrap_database_errors:
  File "/home/ubuntu/e-commerce_backend/myenv/lib/python3.10/site-packages/django/db/utils.py", line 91, in __exit__
    raise dj_exc_value.with_traceback(traceback) from exc_value
  File "/home/ubuntu/e-commerce_backend/myenv/lib/python3.10/site-packages/django/db/backends/utils.py", line 105, in _execute
    return self.cursor.execute(sql, params)
django.db.utils.IntegrityError: null value in column "customer_id" of relation "store_payment" violates not-null constraint
DETAIL:  Failing row contains (11, 1c2ef27f-ace1-4cbd-a805-9da039df2eba, 3.00, PENDING, 2025-08-14 19:27:49.668176+00, null, order_1a6c4680-49ef-4013-bdc6-95dbf2c29e7f_1755198795, null, null, null, KES).

ERROR 2025-08-14 19:30:16,800[PID 87727] django.request- Internal Server Error: /api/webhook/paystack/
Traceback (most recent call last):
  File "/home/ubuntu/e-commerce_backend/myenv/lib/python3.10/site-packages/django/db/models/query.py", line 946, in get_or_create
    return self.get(**kwargs), False
  File "/home/ubuntu/e-commerce_backend/myenv/lib/python3.10/site-packages/django/db/models/query.py", line 633, in get
    raise self.model.DoesNotExist(
store.models.Payment.DoesNotExist: Payment matching query does not exist.

During handling of the above exception, another exception occurred:

Traceback (most recent call last):
  File "/home/ubuntu/e-commerce_backend/myenv/lib/python3.10/site-packages/django/db/backends/utils.py", line 105, in _execute
    return self.cursor.execute(sql, params)
psycopg2.errors.NotNullViolation: null value in column "customer_id" of relation "store_payment" violates not-null constraint
DETAIL:  Failing row contains (12, df31f482-92c5-47d0-a070-ee77a57e01f9, 3.00, PENDING, 2025-08-14 19:30:16.797835+00, null, order_1a6c4680-49ef-4013-bdc6-95dbf2c29e7f_1755199267, null, null, null, KES).


The above exception was the direct cause of the following exception:

Traceback (most recent call last):
  File "/home/ubuntu/e-commerce_backend/myenv/lib/python3.10/site-packages/django/core/handlers/exception.py", line 55, in inner
    response = get_response(request)
  File "/home/ubuntu/e-commerce_backend/myenv/lib/python3.10/site-packages/django/core/handlers/base.py", line 197, in _get_response
    response = wrapped_callback(request, *callback_args, **callback_kwargs)
  File "/home/ubuntu/e-commerce_backend/myenv/lib/python3.10/site-packages/django/views/decorators/csrf.py", line 65, in _view_wrapper
    return view_func(request, *args, **kwargs)
  File "/home/ubuntu/e-commerce_backend/myenv/lib/python3.10/site-packages/django/views/generic/base.py", line 105, in view
    return self.dispatch(request, *args, **kwargs)
  File "/home/ubuntu/e-commerce_backend/myenv/lib/python3.10/site-packages/django/utils/decorators.py", line 48, in _wrapper
    return bound_method(*args, **kwargs)
  File "/home/ubuntu/e-commerce_backend/myenv/lib/python3.10/site-packages/django/views/decorators/csrf.py", line 65, in _view_wrapper
    return view_func(request, *args, **kwargs)
  File "/home/ubuntu/e-commerce_backend/myenv/lib/python3.10/site-packages/rest_framework/views.py", line 515, in dispatch
    response = self.handle_exception(exc)
  File "/home/ubuntu/e-commerce_backend/myenv/lib/python3.10/site-packages/rest_framework/views.py", line 475, in handle_exception
    self.raise_uncaught_exception(exc)
  File "/home/ubuntu/e-commerce_backend/myenv/lib/python3.10/site-packages/rest_framework/views.py", line 486, in raise_uncaught_exception
    raise exc
  File "/home/ubuntu/e-commerce_backend/myenv/lib/python3.10/site-packages/rest_framework/views.py", line 512, in dispatch
    response = handler(request, *args, **kwargs)
  File "/home/ubuntu/e-commerce_backend/myenv/lib/python3.10/site-packages/django/views/decorators/csrf.py", line 65, in _view_wrapper
    return view_func(request, *args, **kwargs)
  File "/home/ubuntu/e-commerce_backend/shopsite/store/webhook.py", line 92, in post
    payment, created = Payment.objects.get_or_create(
  File "/home/ubuntu/e-commerce_backend/myenv/lib/python3.10/site-packages/django/db/models/manager.py", line 87, in manager_method
    return getattr(self.get_queryset(), name)(*args, **kwargs)
  File "/home/ubuntu/e-commerce_backend/myenv/lib/python3.10/site-packages/django/db/models/query.py", line 953, in get_or_create
    return self.create(**params), True
  File "/home/ubuntu/e-commerce_backend/myenv/lib/python3.10/site-packages/django/db/models/query.py", line 663, in create
    obj.save(force_insert=True, using=self.db)
  File "/home/ubuntu/e-commerce_backend/myenv/lib/python3.10/site-packages/django/db/models/base.py", line 902, in save
    self.save_base(
  File "/home/ubuntu/e-commerce_backend/myenv/lib/python3.10/site-packages/django/db/models/base.py", line 1008, in save_base
    updated = self._save_table(
  File "/home/ubuntu/e-commerce_backend/myenv/lib/python3.10/site-packages/django/db/models/base.py", line 1169, in _save_table
    results = self._do_insert(
  File "/home/ubuntu/e-commerce_backend/myenv/lib/python3.10/site-packages/django/db/models/base.py", line 1210, in _do_insert
    return manager._insert(
  File "/home/ubuntu/e-commerce_backend/myenv/lib/python3.10/site-packages/django/db/models/manager.py", line 87, in manager_method
    return getattr(self.get_queryset(), name)(*args, **kwargs)
  File "/home/ubuntu/e-commerce_backend/myenv/lib/python3.10/site-packages/django/db/models/query.py", line 1868, in _insert
    return query.get_compiler(using=using).execute_sql(returning_fields)
  File "/home/ubuntu/e-commerce_backend/myenv/lib/python3.10/site-packages/django/db/models/sql/compiler.py", line 1882, in execute_sql
    cursor.execute(sql, params)
  File "/home/ubuntu/e-commerce_backend/myenv/lib/python3.10/site-packages/django/db/backends/utils.py", line 79, in execute
    return self._execute_with_wrappers(
  File "/home/ubuntu/e-commerce_backend/myenv/lib/python3.10/site-packages/django/db/backends/utils.py", line 92, in _execute_with_wrappers
    return executor(sql, params, many, context)
  File "/home/ubuntu/e-commerce_backend/myenv/lib/python3.10/site-packages/django/db/backends/utils.py", line 100, in _execute
    with self.db.wrap_database_errors:
  File "/home/ubuntu/e-commerce_backend/myenv/lib/python3.10/site-packages/django/db/utils.py", line 91, in __exit__
    raise dj_exc_value.with_traceback(traceback) from exc_value
  File "/home/ubuntu/e-commerce_backend/myenv/lib/python3.10/site-packages/django/db/backends/utils.py", line 105, in _execute
    return self.cursor.execute(sql, params)
django.db.utils.IntegrityError: null value in column "customer_id" of relation "store_payment" violates not-null constraint
DETAIL:  Failing row contains (12, df31f482-92c5-47d0-a070-ee77a57e01f9, 3.00, PENDING, 2025-08-14 19:30:16.797835+00, null, order_1a6c4680-49ef-4013-bdc6-95dbf2c29e7f_1755199267, null, null, null, KES).

ERROR 2025-08-14 19:31:00,914[PID 87727] django.request- Internal Server Error: /api/webhook/paystack/
Traceback (most recent call last):
  File "/home/ubuntu/e-commerce_backend/myenv/lib/python3.10/site-packages/django/db/models/query.py", line 946, in get_or_create
    return self.get(**kwargs), False
  File "/home/ubuntu/e-commerce_backend/myenv/lib/python3.10/site-packages/django/db/models/query.py", line 633, in get
    raise self.model.DoesNotExist(
store.models.Payment.DoesNotExist: Payment matching query does not exist.

During handling of the above exception, another exception occurred:

Traceback (most recent call last):
  File "/home/ubuntu/e-commerce_backend/myenv/lib/python3.10/site-packages/django/db/backends/utils.py", line 105, in _execute
    return self.cursor.execute(sql, params)
psycopg2.errors.NotNullViolation: null value in column "customer_id" of relation "store_payment" violates not-null constraint
DETAIL:  Failing row contains (13, 0170a204-b8d9-43de-a153-42e837201978, 3.00, PENDING, 2025-08-14 19:31:00.911133+00, null, order_1a6c4680-49ef-4013-bdc6-95dbf2c29e7f_1755198795, null, null, null, KES).


The above exception was the direct cause of the following exception:

Traceback (most recent call last):
  File "/home/ubuntu/e-commerce_backend/myenv/lib/python3.10/site-packages/django/core/handlers/exception.py", line 55, in inner
    response = get_response(request)
  File "/home/ubuntu/e-commerce_backend/myenv/lib/python3.10/site-packages/django/core/handlers/base.py", line 197, in _get_response
    response = wrapped_callback(request, *callback_args, **callback_kwargs)
  File "/home/ubuntu/e-commerce_backend/myenv/lib/python3.10/site-packages/django/views/decorators/csrf.py", line 65, in _view_wrapper
    return view_func(request, *args, **kwargs)
  File "/home/ubuntu/e-commerce_backend/myenv/lib/python3.10/site-packages/django/views/generic/base.py", line 105, in view
    return self.dispatch(request, *args, **kwargs)
  File "/home/ubuntu/e-commerce_backend/myenv/lib/python3.10/site-packages/django/utils/decorators.py", line 48, in _wrapper
    return bound_method(*args, **kwargs)
  File "/home/ubuntu/e-commerce_backend/myenv/lib/python3.10/site-packages/django/views/decorators/csrf.py", line 65, in _view_wrapper
    return view_func(request, *args, **kwargs)
  File "/home/ubuntu/e-commerce_backend/myenv/lib/python3.10/site-packages/rest_framework/views.py", line 515, in dispatch
    response = self.handle_exception(exc)
  File "/home/ubuntu/e-commerce_backend/myenv/lib/python3.10/site-packages/rest_framework/views.py", line 475, in handle_exception
    self.raise_uncaught_exception(exc)
  File "/home/ubuntu/e-commerce_backend/myenv/lib/python3.10/site-packages/rest_framework/views.py", line 486, in raise_uncaught_exception
    raise exc
  File "/home/ubuntu/e-commerce_backend/myenv/lib/python3.10/site-packages/rest_framework/views.py", line 512, in dispatch
    response = handler(request, *args, **kwargs)
  File "/home/ubuntu/e-commerce_backend/myenv/lib/python3.10/site-packages/django/views/decorators/csrf.py", line 65, in _view_wrapper
    return view_func(request, *args, **kwargs)
  File "/home/ubuntu/e-commerce_backend/shopsite/store/webhook.py", line 92, in post
    payment, created = Payment.objects.get_or_create(
  File "/home/ubuntu/e-commerce_backend/myenv/lib/python3.10/site-packages/django/db/models/manager.py", line 87, in manager_method
    return getattr(self.get_queryset(), name)(*args, **kwargs)
  File "/home/ubuntu/e-commerce_backend/myenv/lib/python3.10/site-packages/django/db/models/query.py", line 953, in get_or_create
    return self.create(**params), True
  File "/home/ubuntu/e-commerce_backend/myenv/lib/python3.10/site-packages/django/db/models/query.py", line 663, in create
    obj.save(force_insert=True, using=self.db)
  File "/home/ubuntu/e-commerce_backend/myenv/lib/python3.10/site-packages/django/db/models/base.py", line 902, in save
    self.save_base(
  File "/home/ubuntu/e-commerce_backend/myenv/lib/python3.10/site-packages/django/db/models/base.py", line 1008, in save_base
    updated = self._save_table(
  File "/home/ubuntu/e-commerce_backend/myenv/lib/python3.10/site-packages/django/db/models/base.py", line 1169, in _save_table
    results = self._do_insert(
  File "/home/ubuntu/e-commerce_backend/myenv/lib/python3.10/site-packages/django/db/models/base.py", line 1210, in _do_insert
    return manager._insert(
  File "/home/ubuntu/e-commerce_backend/myenv/lib/python3.10/site-packages/django/db/models/manager.py", line 87, in manager_method
    return getattr(self.get_queryset(), name)(*args, **kwargs)
  File "/home/ubuntu/e-commerce_backend/myenv/lib/python3.10/site-packages/django/db/models/query.py", line 1868, in _insert
    return query.get_compiler(using=using).execute_sql(returning_fields)
  File "/home/ubuntu/e-commerce_backend/myenv/lib/python3.10/site-packages/django/db/models/sql/compiler.py", line 1882, in execute_sql
    cursor.execute(sql, params)
  File "/home/ubuntu/e-commerce_backend/myenv/lib/python3.10/site-packages/django/db/backends/utils.py", line 79, in execute
    return self._execute_with_wrappers(
  File "/home/ubuntu/e-commerce_backend/myenv/lib/python3.10/site-packages/django/db/backends/utils.py", line 92, in _execute_with_wrappers
    return executor(sql, params, many, context)
  File "/home/ubuntu/e-commerce_backend/myenv/lib/python3.10/site-packages/django/db/backends/utils.py", line 100, in _execute
    with self.db.wrap_database_errors:
  File "/home/ubuntu/e-commerce_backend/myenv/lib/python3.10/site-packages/django/db/utils.py", line 91, in __exit__
    raise dj_exc_value.with_traceback(traceback) from exc_value
  File "/home/ubuntu/e-commerce_backend/myenv/lib/python3.10/site-packages/django/db/backends/utils.py", line 105, in _execute
    return self.cursor.execute(sql, params)
django.db.utils.IntegrityError: null value in column "customer_id" of relation "store_payment" violates not-null constraint
DETAIL:  Failing row contains (13, 0170a204-b8d9-43de-a153-42e837201978, 3.00, PENDING, 2025-08-14 19:31:00.911133+00, null, order_1a6c4680-49ef-4013-bdc6-95dbf2c29e7f_1755198795, null, null, null, KES).

ERROR 2025-08-14 19:33:30,697[PID 87727] django.request- Internal Server Error: /api/webhook/paystack/
Traceback (most recent call last):
  File "/home/ubuntu/e-commerce_backend/myenv/lib/python3.10/site-packages/django/db/models/query.py", line 946, in get_or_create
    return self.get(**kwargs), False
  File "/home/ubuntu/e-commerce_backend/myenv/lib/python3.10/site-packages/django/db/models/query.py", line 633, in get
    raise self.model.DoesNotExist(
store.models.Payment.DoesNotExist: Payment matching query does not exist.

During handling of the above exception, another exception occurred:

Traceback (most recent call last):
  File "/home/ubuntu/e-commerce_backend/myenv/lib/python3.10/site-packages/django/db/backends/utils.py", line 105, in _execute
    return self.cursor.execute(sql, params)
psycopg2.errors.NotNullViolation: null value in column "customer_id" of relation "store_payment" violates not-null constraint
DETAIL:  Failing row contains (14, e749a399-1af9-4d67-a9a2-fe31270b80f2, 3.00, PENDING, 2025-08-14 19:33:30.694953+00, null, order_1a6c4680-49ef-4013-bdc6-95dbf2c29e7f_1755199267, null, null, null, KES).


The above exception was the direct cause of the following exception:

Traceback (most recent call last):
  File "/home/ubuntu/e-commerce_backend/myenv/lib/python3.10/site-packages/django/core/handlers/exception.py", line 55, in inner
    response = get_response(request)
  File "/home/ubuntu/e-commerce_backend/myenv/lib/python3.10/site-packages/django/core/handlers/base.py", line 197, in _get_response
    response = wrapped_callback(request, *callback_args, **callback_kwargs)
  File "/home/ubuntu/e-commerce_backend/myenv/lib/python3.10/site-packages/django/views/decorators/csrf.py", line 65, in _view_wrapper
    return view_func(request, *args, **kwargs)
  File "/home/ubuntu/e-commerce_backend/myenv/lib/python3.10/site-packages/django/views/generic/base.py", line 105, in view
    return self.dispatch(request, *args, **kwargs)
  File "/home/ubuntu/e-commerce_backend/myenv/lib/python3.10/site-packages/django/utils/decorators.py", line 48, in _wrapper
    return bound_method(*args, **kwargs)
  File "/home/ubuntu/e-commerce_backend/myenv/lib/python3.10/site-packages/django/views/decorators/csrf.py", line 65, in _view_wrapper
    return view_func(request, *args, **kwargs)
  File "/home/ubuntu/e-commerce_backend/myenv/lib/python3.10/site-packages/rest_framework/views.py", line 515, in dispatch
    response = self.handle_exception(exc)
  File "/home/ubuntu/e-commerce_backend/myenv/lib/python3.10/site-packages/rest_framework/views.py", line 475, in handle_exception
    self.raise_uncaught_exception(exc)
  File "/home/ubuntu/e-commerce_backend/myenv/lib/python3.10/site-packages/rest_framework/views.py", line 486, in raise_uncaught_exception
    raise exc
  File "/home/ubuntu/e-commerce_backend/myenv/lib/python3.10/site-packages/rest_framework/views.py", line 512, in dispatch
    response = handler(request, *args, **kwargs)
  File "/home/ubuntu/e-commerce_backend/myenv/lib/python3.10/site-packages/django/views/decorators/csrf.py", line 65, in _view_wrapper
    return view_func(request, *args, **kwargs)
  File "/home/ubuntu/e-commerce_backend/shopsite/store/webhook.py", line 92, in post
    payment, created = Payment.objects.get_or_create(
  File "/home/ubuntu/e-commerce_backend/myenv/lib/python3.10/site-packages/django/db/models/manager.py", line 87, in manager_method
    return getattr(self.get_queryset(), name)(*args, **kwargs)
  File "/home/ubuntu/e-commerce_backend/myenv/lib/python3.10/site-packages/django/db/models/query.py", line 953, in get_or_create
    return self.create(**params), True
  File "/home/ubuntu/e-commerce_backend/myenv/lib/python3.10/site-packages/django/db/models/query.py", line 663, in create
    obj.save(force_insert=True, using=self.db)
  File "/home/ubuntu/e-commerce_backend/myenv/lib/python3.10/site-packages/django/db/models/base.py", line 902, in save
    self.save_base(
  File "/home/ubuntu/e-commerce_backend/myenv/lib/python3.10/site-packages/django/db/models/base.py", line 1008, in save_base
    updated = self._save_table(
  File "/home/ubuntu/e-commerce_backend/myenv/lib/python3.10/site-packages/django/db/models/base.py", line 1169, in _save_table
    results = self._do_insert(
  File "/home/ubuntu/e-commerce_backend/myenv/lib/python3.10/site-packages/django/db/models/base.py", line 1210, in _do_insert
    return manager._insert(
  File "/home/ubuntu/e-commerce_backend/myenv/lib/python3.10/site-packages/django/db/models/manager.py", line 87, in manager_method
    return getattr(self.get_queryset(), name)(*args, **kwargs)
  File "/home/ubuntu/e-commerce_backend/myenv/lib/python3.10/site-packages/django/db/models/query.py", line 1868, in _insert
    return query.get_compiler(using=using).execute_sql(returning_fields)
  File "/home/ubuntu/e-commerce_backend/myenv/lib/python3.10/site-packages/django/db/models/sql/compiler.py", line 1882, in execute_sql
    cursor.execute(sql, params)
  File "/home/ubuntu/e-commerce_backend/myenv/lib/python3.10/site-packages/django/db/backends/utils.py", line 79, in execute
    return self._execute_with_wrappers(
  File "/home/ubuntu/e-commerce_backend/myenv/lib/python3.10/site-packages/django/db/backends/utils.py", line 92, in _execute_with_wrappers
    return executor(sql, params, many, context)
  File "/home/ubuntu/e-commerce_backend/myenv/lib/python3.10/site-packages/django/db/backends/utils.py", line 100, in _execute
    with self.db.wrap_database_errors:
  File "/home/ubuntu/e-commerce_backend/myenv/lib/python3.10/site-packages/django/db/utils.py", line 91, in __exit__
    raise dj_exc_value.with_traceback(traceback) from exc_value
  File "/home/ubuntu/e-commerce_backend/myenv/lib/python3.10/site-packages/django/db/backends/utils.py", line 105, in _execute
    return self.cursor.execute(sql, params)
django.db.utils.IntegrityError: null value in column "customer_id" of relation "store_payment" violates not-null constraint
DETAIL:  Failing row contains (14, e749a399-1af9-4d67-a9a2-fe31270b80f2, 3.00, PENDING, 2025-08-14 19:33:30.694953+00, null, order_1a6c4680-49ef-4013-bdc6-95dbf2c29e7f_1755199267, null, null, null, KES).

ERROR 2025-08-14 19:36:53,779[PID 87727] django.request- Internal Server Error: /api/webhook/paystack/
Traceback (most recent call last):
  File "/home/ubuntu/e-commerce_backend/myenv/lib/python3.10/site-packages/django/db/models/query.py", line 946, in get_or_create
    return self.get(**kwargs), False
  File "/home/ubuntu/e-commerce_backend/myenv/lib/python3.10/site-packages/django/db/models/query.py", line 633, in get
    raise self.model.DoesNotExist(
store.models.Payment.DoesNotExist: Payment matching query does not exist.

During handling of the above exception, another exception occurred:

Traceback (most recent call last):
  File "/home/ubuntu/e-commerce_backend/myenv/lib/python3.10/site-packages/django/db/backends/utils.py", line 105, in _execute
    return self.cursor.execute(sql, params)
psycopg2.errors.NotNullViolation: null value in column "customer_id" of relation "store_payment" violates not-null constraint
DETAIL:  Failing row contains (15, d5df4ea5-0c41-4d5b-a480-bd41ae9bdde5, 3.00, PENDING, 2025-08-14 19:36:53.776962+00, null, order_1a6c4680-49ef-4013-bdc6-95dbf2c29e7f_1755199267, null, null, null, KES).


The above exception was the direct cause of the following exception:

Traceback (most recent call last):
  File "/home/ubuntu/e-commerce_backend/myenv/lib/python3.10/site-packages/django/core/handlers/exception.py", line 55, in inner
    response = get_response(request)
  File "/home/ubuntu/e-commerce_backend/myenv/lib/python3.10/site-packages/django/core/handlers/base.py", line 197, in _get_response
    response = wrapped_callback(request, *callback_args, **callback_kwargs)
  File "/home/ubuntu/e-commerce_backend/myenv/lib/python3.10/site-packages/django/views/decorators/csrf.py", line 65, in _view_wrapper
    return view_func(request, *args, **kwargs)
  File "/home/ubuntu/e-commerce_backend/myenv/lib/python3.10/site-packages/django/views/generic/base.py", line 105, in view
    return self.dispatch(request, *args, **kwargs)
  File "/home/ubuntu/e-commerce_backend/myenv/lib/python3.10/site-packages/django/utils/decorators.py", line 48, in _wrapper
    return bound_method(*args, **kwargs)
  File "/home/ubuntu/e-commerce_backend/myenv/lib/python3.10/site-packages/django/views/decorators/csrf.py", line 65, in _view_wrapper
    return view_func(request, *args, **kwargs)
  File "/home/ubuntu/e-commerce_backend/myenv/lib/python3.10/site-packages/rest_framework/views.py", line 515, in dispatch
    response = self.handle_exception(exc)
  File "/home/ubuntu/e-commerce_backend/myenv/lib/python3.10/site-packages/rest_framework/views.py", line 475, in handle_exception
    self.raise_uncaught_exception(exc)
  File "/home/ubuntu/e-commerce_backend/myenv/lib/python3.10/site-packages/rest_framework/views.py", line 486, in raise_uncaught_exception
    raise exc
  File "/home/ubuntu/e-commerce_backend/myenv/lib/python3.10/site-packages/rest_framework/views.py", line 512, in dispatch
    response = handler(request, *args, **kwargs)
  File "/home/ubuntu/e-commerce_backend/myenv/lib/python3.10/site-packages/django/views/decorators/csrf.py", line 65, in _view_wrapper
    return view_func(request, *args, **kwargs)
  File "/home/ubuntu/e-commerce_backend/shopsite/store/webhook.py", line 92, in post
    payment, created = Payment.objects.get_or_create(
  File "/home/ubuntu/e-commerce_backend/myenv/lib/python3.10/site-packages/django/db/models/manager.py", line 87, in manager_method
    return getattr(self.get_queryset(), name)(*args, **kwargs)
  File "/home/ubuntu/e-commerce_backend/myenv/lib/python3.10/site-packages/django/db/models/query.py", line 953, in get_or_create
    return self.create(**params), True
  File "/home/ubuntu/e-commerce_backend/myenv/lib/python3.10/site-packages/django/db/models/query.py", line 663, in create
    obj.save(force_insert=True, using=self.db)
  File "/home/ubuntu/e-commerce_backend/myenv/lib/python3.10/site-packages/django/db/models/base.py", line 902, in save
    self.save_base(
  File "/home/ubuntu/e-commerce_backend/myenv/lib/python3.10/site-packages/django/db/models/base.py", line 1008, in save_base
    updated = self._save_table(
  File "/home/ubuntu/e-commerce_backend/myenv/lib/python3.10/site-packages/django/db/models/base.py", line 1169, in _save_table
    results = self._do_insert(
  File "/home/ubuntu/e-commerce_backend/myenv/lib/python3.10/site-packages/django/db/models/base.py", line 1210, in _do_insert
    return manager._insert(
  File "/home/ubuntu/e-commerce_backend/myenv/lib/python3.10/site-packages/django/db/models/manager.py", line 87, in manager_method
    return getattr(self.get_queryset(), name)(*args, **kwargs)
  File "/home/ubuntu/e-commerce_backend/myenv/lib/python3.10/site-packages/django/db/models/query.py", line 1868, in _insert
    return query.get_compiler(using=using).execute_sql(returning_fields)
  File "/home/ubuntu/e-commerce_backend/myenv/lib/python3.10/site-packages/django/db/models/sql/compiler.py", line 1882, in execute_sql
    cursor.execute(sql, params)
  File "/home/ubuntu/e-commerce_backend/myenv/lib/python3.10/site-packages/django/db/backends/utils.py", line 79, in execute
    return self._execute_with_wrappers(
  File "/home/ubuntu/e-commerce_backend/myenv/lib/python3.10/site-packages/django/db/backends/utils.py", line 92, in _execute_with_wrappers
    return executor(sql, params, many, context)
  File "/home/ubuntu/e-commerce_backend/myenv/lib/python3.10/site-packages/django/db/backends/utils.py", line 100, in _execute
    with self.db.wrap_database_errors:
  File "/home/ubuntu/e-commerce_backend/myenv/lib/python3.10/site-packages/django/db/utils.py", line 91, in __exit__
    raise dj_exc_value.with_traceback(traceback) from exc_value
  File "/home/ubuntu/e-commerce_backend/myenv/lib/python3.10/site-packages/django/db/backends/utils.py", line 105, in _execute
    return self.cursor.execute(sql, params)
django.db.utils.IntegrityError: null value in column "customer_id" of relation "store_payment" violates not-null constraint
DETAIL:  Failing row contains (15, d5df4ea5-0c41-4d5b-a480-bd41ae9bdde5, 3.00, PENDING, 2025-08-14 19:36:53.776962+00, null, order_1a6c4680-49ef-4013-bdc6-95dbf2c29e7f_1755199267, null, null, null, KES).

ERROR 2025-08-14 19:40:05,708[PID 87727] django.request- Internal Server Error: /api/webhook/paystack/
Traceback (most recent call last):
  File "/home/ubuntu/e-commerce_backend/myenv/lib/python3.10/site-packages/django/db/models/query.py", line 946, in get_or_create
    return self.get(**kwargs), False
  File "/home/ubuntu/e-commerce_backend/myenv/lib/python3.10/site-packages/django/db/models/query.py", line 633, in get
    raise self.model.DoesNotExist(
store.models.Payment.DoesNotExist: Payment matching query does not exist.

During handling of the above exception, another exception occurred:

Traceback (most recent call last):
  File "/home/ubuntu/e-commerce_backend/myenv/lib/python3.10/site-packages/django/db/backends/utils.py", line 105, in _execute
    return self.cursor.execute(sql, params)
psycopg2.errors.NotNullViolation: null value in column "customer_id" of relation "store_payment" violates not-null constraint
DETAIL:  Failing row contains (16, fb1bc717-b7ec-425d-96c1-20048585ef42, 3.00, PENDING, 2025-08-14 19:40:05.704964+00, null, order_1a6c4680-49ef-4013-bdc6-95dbf2c29e7f_1755199267, null, null, null, KES).


The above exception was the direct cause of the following exception:

Traceback (most recent call last):
  File "/home/ubuntu/e-commerce_backend/myenv/lib/python3.10/site-packages/django/core/handlers/exception.py", line 55, in inner
    response = get_response(request)
  File "/home/ubuntu/e-commerce_backend/myenv/lib/python3.10/site-packages/django/core/handlers/base.py", line 197, in _get_response
    response = wrapped_callback(request, *callback_args, **callback_kwargs)
  File "/home/ubuntu/e-commerce_backend/myenv/lib/python3.10/site-packages/django/views/decorators/csrf.py", line 65, in _view_wrapper
    return view_func(request, *args, **kwargs)
  File "/home/ubuntu/e-commerce_backend/myenv/lib/python3.10/site-packages/django/views/generic/base.py", line 105, in view
    return self.dispatch(request, *args, **kwargs)
  File "/home/ubuntu/e-commerce_backend/myenv/lib/python3.10/site-packages/django/utils/decorators.py", line 48, in _wrapper
    return bound_method(*args, **kwargs)
  File "/home/ubuntu/e-commerce_backend/myenv/lib/python3.10/site-packages/django/views/decorators/csrf.py", line 65, in _view_wrapper
    return view_func(request, *args, **kwargs)
  File "/home/ubuntu/e-commerce_backend/myenv/lib/python3.10/site-packages/rest_framework/views.py", line 515, in dispatch
    response = self.handle_exception(exc)
  File "/home/ubuntu/e-commerce_backend/myenv/lib/python3.10/site-packages/rest_framework/views.py", line 475, in handle_exception
    self.raise_uncaught_exception(exc)
  File "/home/ubuntu/e-commerce_backend/myenv/lib/python3.10/site-packages/rest_framework/views.py", line 486, in raise_uncaught_exception
    raise exc
  File "/home/ubuntu/e-commerce_backend/myenv/lib/python3.10/site-packages/rest_framework/views.py", line 512, in dispatch
    response = handler(request, *args, **kwargs)
  File "/home/ubuntu/e-commerce_backend/myenv/lib/python3.10/site-packages/django/views/decorators/csrf.py", line 65, in _view_wrapper
    return view_func(request, *args, **kwargs)
  File "/home/ubuntu/e-commerce_backend/shopsite/store/webhook.py", line 92, in post
    payment, created = Payment.objects.get_or_create(
  File "/home/ubuntu/e-commerce_backend/myenv/lib/python3.10/site-packages/django/db/models/manager.py", line 87, in manager_method
    return getattr(self.get_queryset(), name)(*args, **kwargs)
  File "/home/ubuntu/e-commerce_backend/myenv/lib/python3.10/site-packages/django/db/models/query.py", line 953, in get_or_create
    return self.create(**params), True
  File "/home/ubuntu/e-commerce_backend/myenv/lib/python3.10/site-packages/django/db/models/query.py", line 663, in create
    obj.save(force_insert=True, using=self.db)
  File "/home/ubuntu/e-commerce_backend/myenv/lib/python3.10/site-packages/django/db/models/base.py", line 902, in save
    self.save_base(
  File "/home/ubuntu/e-commerce_backend/myenv/lib/python3.10/site-packages/django/db/models/base.py", line 1008, in save_base
    updated = self._save_table(
  File "/home/ubuntu/e-commerce_backend/myenv/lib/python3.10/site-packages/django/db/models/base.py", line 1169, in _save_table
    results = self._do_insert(
  File "/home/ubuntu/e-commerce_backend/myenv/lib/python3.10/site-packages/django/db/models/base.py", line 1210, in _do_insert
    return manager._insert(
  File "/home/ubuntu/e-commerce_backend/myenv/lib/python3.10/site-packages/django/db/models/manager.py", line 87, in manager_method
    return getattr(self.get_queryset(), name)(*args, **kwargs)
  File "/home/ubuntu/e-commerce_backend/myenv/lib/python3.10/site-packages/django/db/models/query.py", line 1868, in _insert
    return query.get_compiler(using=using).execute_sql(returning_fields)
  File "/home/ubuntu/e-commerce_backend/myenv/lib/python3.10/site-packages/django/db/models/sql/compiler.py", line 1882, in execute_sql
    cursor.execute(sql, params)
  File "/home/ubuntu/e-commerce_backend/myenv/lib/python3.10/site-packages/django/db/backends/utils.py", line 79, in execute
    return self._execute_with_wrappers(
  File "/home/ubuntu/e-commerce_backend/myenv/lib/python3.10/site-packages/django/db/backends/utils.py", line 92, in _execute_with_wrappers
    return executor(sql, params, many, context)
  File "/home/ubuntu/e-commerce_backend/myenv/lib/python3.10/site-packages/django/db/backends/utils.py", line 100, in _execute
    with self.db.wrap_database_errors:
  File "/home/ubuntu/e-commerce_backend/myenv/lib/python3.10/site-packages/django/db/utils.py", line 91, in __exit__
    raise dj_exc_value.with_traceback(traceback) from exc_value
  File "/home/ubuntu/e-commerce_backend/myenv/lib/python3.10/site-packages/django/db/backends/utils.py", line 105, in _execute
    return self.cursor.execute(sql, params)
django.db.utils.IntegrityError: null value in column "customer_id" of relation "store_payment" violates not-null constraint
DETAIL:  Failing row contains (16, fb1bc717-b7ec-425d-96c1-20048585ef42, 3.00, PENDING, 2025-08-14 19:40:05.704964+00, null, order_1a6c4680-49ef-4013-bdc6-95dbf2c29e7f_1755199267, null, null, null, KES).

